Workbook

Sheet standalone- balance sheet
A1: an interpretation of the financial position of the company purely based on the ratios computed. | B1: 45008 | C1: 45007 | D1: 45006 | E1: 45005 | F1: 45004
B2: 12 mths | C2: 12 mths | D2: 12 mths | E2: 12 mths | F2: 12 mths
A3: EQUITIES AND LIABILITIES
A4: SHAREHOLDER'S FUNDS
A5: Equity Share Capital | B5: 47.59 | C5: 47.57 | D5: 47.57 | E5: 29.02 | F5: 28.85
A6: TOTAL SHARE CAPITAL | B6: 47.59 | C6: 47.57 | D6: 47.57 | E6: 29.02 | F6: 28.85
A7: Reserves and Surplus | B7: 718.69 | C7: 599.57 | D7: 515.92 | E7: 149.73 | F7: 100.31
A8: TOTAL RESERVES AND SURPLUS | B8: 718.69 | C8: 599.57 | D8: 515.92 | E8: 149.73 | F8: 100.31
A9: TOTAL SHAREHOLDERS FUNDS | B9: 776.13 | C9: 649.86 | D9: 563.49 | E9: 178.75 | F9: 129.16
A10: NON-CURRENT LIABILITIES
A11: Long Term Borrowings | B11: 0 | C11: 7.74 | D11: 0 | E11: 27.54 | F11: 32.32
A12: Deferred Tax Liabilities [Net] | B12: 6.94 | C12: 8.47 | D12: 6.95 | E12: 6.97 | F12: 2.1
A13: Other Long Term Liabilities | B13: 11.74 | C13: 4.84 | D13: 9.79 | E13: 3.85 | F13: 3.17
A14: Long Term Provisions | B14: 2.72 | C14: 4.75 | D14: 2.53 | E14: 1.3 | F14: 0
A15: TOTAL NON-CURRENT LIABILITIES | B15: 21.4 | C15: 25.81 | D15: 19.27 | E15: 39.65 | F15: 37.59
A16: CURRENT LIABILITIES
A17: Short Term Borrowings | B17: 0 | C17: 0 | D17: 0 | E17: 17.97 | F17: 28.69
A18: Trade Payables | B18: 210.58 | C18: 201.41 | D18: 185.57 | E18: 138.59 | F18: 136.24
A19: Other Current Liabilities | B19: 46.66 | C19: 40.54 | D19: 41.15 | E19: 27.63 | F19: 23.19
A20: Short Term Provisions | B20: 6.85 | C20: 2.27 | D20: 1.68 | E20: 1.06 | F20: 0
A21: TOTAL CURRENT LIABILITIES | B21: 264.08 | C21: 244.22 | D21: 228.4 | E21: 185.25 | F21: 188.13
A22: TOTAL CAPITAL AND LIABILITIES | B22: 1061.6 | C22: 919.89 | D22: 811.16 | E22: 421.96 | F22: 373.18
A24: ASSETS
A25: NON-CURRENT ASSETS
A26: Tangible Assets | B26: 233.84 | C26: 222.4 | D26: 218.32 | E26: 169.83 | F26: 117.57
A27: Intangible Assets | B27: 30.86 | C27: 30.94 | D27: 31.01 | E27: 30.92 | F27: 30.98
A28: Capital Work-In-Progress | B28: 250.91 | C28: 50.97 | D28: 3.12 | E28: 1.09 | F28: 4.4
A29: Other Assets | B29: 0 | C29: 0 | D29: 0 | E29: 0 | F29: 0
A30: FIXED ASSETS | B30: 515.61 | C30: 304.31 | D30: 252.45 | E30: 201.84 | F30: 152.95
A31: Non-Current Investments | B31: 0 | C31: 0 | D31: 0 | E31: 0 | F31: 0
A32: Deferred Tax Assets [Net] | B32: 0 | C32: 0 | D32: 0 | E32: 0 | F32: 0
A33: Long Term Loans And Advances | B33: 0 | C33: 0 | D33: 0.88 | E33: 5.48 | F33: 4.07
A34: Other Non-Current Assets | B34: 27.26 | C34: 43.19 | D34: 15.44 | E34: 3.41 | F34: 5.92
A35: TOTAL NON-CURRENT ASSETS | B35: 542.86 | C35: 347.5 | D35: 268.76 | E35: 210.73 | F35: 162.95
A36: CURRENT ASSETS
A37: Current Investments | B37: 131.69 | C37: 173.1 | D37: 49.68 | E37: 20.84 | F37: 19.7
A38: Inventories | B38: 117.66 | C38: 117.72 | D38: 94.67 | E38: 76.76 | F38: 69.33
A39: Trade Receivables | B39: 200.11 | C39: 171.65 | D39: 121.19 | E39: 104.47 | F39: 103.85
A40: Cash And Cash Equivalents | B40: 48.79 | C40: 99.62 | D40: 258.31 | E40: 5.68 | F40: 13.85
A41: Short Term Loans And Advances | B41: 0 | C41: 0 | D41: 3.67 | E41: 0.32 | F41: 0.33
...

Sheet standalone-income statemen
A2: Standalone Profit & Loss account | B2: ------------------- in Rs. Cr. -------------------
B3: 45008 | C3: 45007 | D3: 45006 | E3: 45005 | F3: 45004
B5: 12 mths | C5: 12 mths | D5: 12 mths | E5: 12 mths | F5: 12 mths
A7: INCOME
A8: Revenue From Operations [Gross] | B8: 1068.33 | C8: 901.27 | D8: 719.95 | E8: 621.82 | F8: 532.77
A9: Revenue From Operations [Net] | B9: 1068.33 | C9: 901.27 | D9: 719.95 | E9: 621.82 | F9: 532.77
A10: Other Operating Revenues | B10: 5.01 | C10: 4.71 | D10: 3.37 | E10: 2.97 | F10: 2.86
A11: Total Operating Revenues | B11: 1073.33 | C11: 905.97 | D11: 723.32 | E11: 624.79 | F11: 535.63
A12: Other Income | B12: 10.07 | C12: 10.89 | D12: 3.59 | E12: 1.61 | F12: 1.62
A13: Total Revenue | B13: 1083.4 | C13: 916.87 | D13: 726.92 | E13: 626.41 | F13: 537.25
A14: EXPENSES
A15: Cost Of Materials Consumed | B15: 576.33 | C15: 508.88 | D15: 363.95 | E15: 321.13 | F15: 296.52
A16: Purchase Of Stock-In Trade | B16: 20.57 | C16: 19.26 | D16: 17.83 | E16: 10.86 | F16: 8.13
A17: Changes In Inventories Of FG,WIP And Stock-In Trade | B17: -1.64 | C17: -14.62 | D17: -5.26 | E17: -10.03 | F17: -6.12
A18: Employee Benefit Expenses | B18: 73.1 | C18: 56.33 | D18: 48.31 | E18: 41.99 | F18: 36.38
A19: Finance Costs | B19: 1.38 | C19: 1.33 | D19: 3.81 | E19: 5.59 | F19: 4.66
A20: Depreciation And Amortisation Expenses | B20: 34.35 | C20: 31.25 | D20: 24.39 | E20: 19.61 | F20: 17.05
A21: Other Expenses | B21: 223.45 | C21: 200.14 | D21: 175.98 | E21: 169.82 | F21: 146.61
A22: Total Expenses | B22: 927.52 | C22: 802.57 | D22: 629.01 | E22: 558.98 | F22: 503.23
B23: 45008 | C23: 45007 | D23: 45006 | E23: 45005 | F23: 45004
B25: 12 mths | C25: 12 mths | D25: 12 mths | E25: 12 mths | F25: 12 mths
A27: Profit/Loss Before Exceptional, ExtraOrdinary Items And Tax | B27: 155.88 | C27: 114.3 | D27: 97.91 | E27: 67.43 | F27: 34.02
A28: Exceptional Items | B28: 0 | C28: 0 | D28: 0 | E28: 0 | F28: -0.3
A29: Profit/Loss Before Tax | B29: 155.88 | C29: 114.3 | D29: 97.91 | E29: 67.43 | F29: 33.71
A30: Tax Expenses-Continued Operations
A31: Current Tax | B31: 41.8 | C31: 28.77 | D31: 25.55 | E31: 14.71 | F31: 4.82
A32: Deferred Tax | B32: -1.53 | C32: 1.47 | D32: 2.35 | E32: 4.9 | F32: 2.02
A33: Tax For Earlier Years | B33: -16.33 | C33: 0 | D33: -0.85 | E33: 0 | F33: 0
A34: Total Tax Expenses | B34: 23.94 | C34: 30.25 | D34: 27.06 | E34: 19.61 | F34: 6.84
A35: Profit/Loss After Tax And Before ExtraOrdinary Items | B35: 131.94 | C35: 84.05 | D35: 70.85 | E35: 47.81 | F35: 26.87
A36: Profit/Loss From Continuing Operations | B36: 131.94 | C36: 84.05 | D36: 70.85 | E36: 47.81 | F36: 26.87
A37: Profit/Loss For The Period | B37: 131.94 | C37: 84.05 | D37: 70.85 | E37: 47.81 | F37: 26.87
B38: 45008 | C38: 45007 | D38: 45006 | E38: 45005 | F38: 45004
B40: 12 mths | C40: 12 mths | D40: 12 mths | E40: 12 mths | F40: 12 mths
A42: OTHER ADDITIONAL INFORMATION
A43: EARNINGS PER SHARE
A44: Basic EPS (Rs.) | B44: 27.73 | C44: 17.67 | D44: 15.55 | E44: 16.5 | F44: 9.32
A45: Diluted EPS (Rs.) | B45: 27.67 | C45: 17.67 | D45: 15.55 | E45: 10.5 | F45: 5.9
A46: VALUE OF IMPORTED AND INDIGENIOUS RAW MATERIALS
A47: STORES, SPARES AND LOOSE TOOLS
...

Sheet standalone- cash flow
A1: Indigo Paints | B1: Previous Years »
A2: Cash Flow | B2: ------------------- in Rs. Cr. -------------------
B4: 45008 | C4: 45008 | D4: 45007 | E4: 45007 | F4: 45006
B6: 12 mths | C6: 12 mths | D6: 12 mths | E6: 12 mths | F6: 12 mths
A8: Net Profit/Loss Before Extraordinary Items And Tax | B8: 155.88 | C8: 0 | D8: 114.3 | E8: 0 | F8: 0
A9: Net CashFlow From Operating Activities | B9: 116.11 | C9: 0 | D9: 65.19 | E9: 0 | F9: 0
A10: Net Cash Used In Investing Activities | B10: -84.4 | C10: 0 | D10: -69.16 | E10: 0 | F10: 0
A11: Net Cash Used From Financing Activities | B11: -20.06 | C11: 0 | D11: -5.29 | E11: 0 | F11: 0
A12: Net Inc/Dec In Cash And Cash Equivalents | B12: 11.65 | C12: 0 | D12: -9.27 | E12: 0 | F12: 0
A13: Cash And Cash Equivalents Begin of Year | B13: 35.53 | C13: 0 | D13: 44.8 | E13: 0 | F13: 0
A14: Cash And Cash Equivalents End Of Year | B14: 47.18 | C14: 0 | D14: 35.53 | E14: 0 | F14: 0

Sheet KPC_Ratios
D1: Computations - Any Comments | F1: 2023 | G1: 2022 | H1: 2021 | I1: 2020 | J1: 2019
F2: Computations | K2: Intepretation | L2: Peer Comparison - Only 2023 (Industry Average)
B3: LIQUIDITY RATIO
B4: Current Ratio | C4: Current Assets / Current Liabilities | E4: A simple measure that estimates whether the business can pay short term debts. Ideal ratio is 2 : 1. | F4: ='standalone- balance sheet'!B43/'standalone- balance sheet'!B21 -> 1.964329 | G4: ='standalone- balance sheet'!C43/'standalone- balance sheet'!C21 -> 2.3437474 | H4: ='standalone- balance sheet'!D43/'standalone- balance sheet'!D21 -> 2.3747811 | I4: ='standalone- balance sheet'!E43/'standalone- balance sheet'!E21 -> 1.1402429 | J4: ='standalone- balance sheet'!F43/'standalone- balance sheet'!F21 -> 1.1175251 | K4: The current ratio indicates strong short-term liquidity of the company and how quickly it can fulfil the short-term liabilities it holds using the current assets the company holds. The current ratio for Indigo Paints is slightly higher than the industry average which is a good sign for the company. It is not too high than the industry average, so it shows that the management is effectively utilising its assets and the company provides a sense of low risk and stability for investors/shareholders. | L4: 1.73
B5: Quick Ratio | C5: Quick Assets / Current Liabilities | E5: It measures the ability to meet current debt immediately. Ideal ratio is 1 : 1. | F5: =F6/'standalone- balance sheet'!B21 -> 1.5187822 | G5: =G6/'standalone- balance sheet'!C21 -> 1.861723 | H5: =H6/'standalone- balance sheet'!D21 -> 1.960289 | I5: =I6/'standalone- balance sheet'!E21 -> 0.72588394 | J5: =J6/'standalone- balance sheet'!F21 -> 0.74900335 | K5: Quick Ratio is a better indicator of the liquidity of a company as it excludes inventory and other assets that can not be quickly converted to cash. This gives a better idea of how the company manages its assets to fulfil short-term liabilities. Again the quick ratio of Indigo is higher than the industry average which shows that the company is at a more low risk, liquid company compared to majority of its peers making it an ideal choice for investors/ shareholders | L5: 1.17
D6: Quick Assets = Current Assets - Inventory - Prepaid Expenses | F6: ='standalone- balance sheet'!B43-'standalone- balance sheet'!B38 -> 401.08 | G6: ='standalone- balance sheet'!C43-'standalone- balance sheet'!C38 -> 454.67 | H6: ='standalone- balance sheet'!D43-'standalone- balance sheet'!D38 -> 447.73 | I6: ='standalone- balance sheet'!E43-'standalone- balance sheet'!E38 -> 134.47 | J6: ='standalone- balance sheet'!F43-'standalone- balance sheet'!F38 -> 140.91
B7: Cash Ratio | C7: Cash and Bank Balance + Marketable Securities / Current Liabilities | E7: It measures absolute liquidity of the business. | F7: ='standalone- balance sheet'!B40/'standalone- balance sheet'!B21 -> 0.18475462 | G7: ='standalone- balance sheet'!C40/'standalone- balance sheet'!C21 -> 0.4079109 | H7: ='standalone- balance sheet'!D40/'standalone- balance sheet'!D21 -> 1.1309545 | I7: ='standalone- balance sheet'!E40/'standalone- balance sheet'!E21 -> 0.030661269 | J7: ='standalone- balance sheet'!F40/'standalone- balance sheet'!F21 -> 0.073619306
B8: CAPITAL STRUCTURE RATIO
B9: Equity Ratio | C9: Shareholders Equity / Capital Employed | D9: Capital employed taken by finance people: total assets-current liabilities | E9: It indicates owner’s fund in companies to total fund invested. | F9: ='standalone- balance sheet'!B5/F10 -> 0.059672485 | G9: ='standalone- balance sheet'!C5/G10 -> 0.070404191 | H9: ='standalone- balance sheet'!D5/H10 -> 0.081628801 | I9: ='standalone- balance sheet'!E5/I10 -> 0.12259727 | J9: ='standalone- balance sheet'!F5/J10 -> 0.15590381
D10: Capital Employed | F10: ='standalone- balance sheet'!B44-'standalone- balance sheet'!B21 -> 797.52 | G10: ='standalone- balance sheet'!C44-'standalone- balance sheet'!C21 -> 675.67 | H10: ='standalone- balance sheet'!D44-'standalone- balance sheet'!D21 -> 582.76 | I10: ='standalone- balance sheet'!E44-'standalone- balance sheet'!E21 -> 236.71 | J10: ='standalone- balance sheet'!F44-'standalone- balance sheet'!F21 -> 185.05
B11: Debt to Equity Ratio | C11: Long Term Debt / Shareholder’s Equity | E11: It indicates the composition of capital structure in terms of debt and equity | F11: ='standalone- balance sheet'!B11/'standalone- balance sheet'!B9 -> 0 | G11: ='standalone- balance sheet'!C11/'standalone- balance sheet'!C9 -> 0.011910258 | H11: ='standalone- balance sheet'!D11/'standalone- balance sheet'!D9 -> 0 | I11: ='standalone- balance sheet'!E11/'standalone- balance sheet'!E9 -> 0.15406993 | J11: ='standalone- balance sheet'!F11/'standalone- balance sheet'!F9 -> 0.25023227 | K11: It is a good sign if a company has a debt-to-equity ratio of less than 1. This indicates that the company has a low debt and can fund the company's operations from the shareholder's equity and does not rely much on external debt. Indigo has the lowest debt-to-equity ratio as compared to all its peers, almost negligible, which is a very good sign for investors. This shows that the company is in a good position in terms of financial risk. It shows that the company is not burdened by debt and is in a good financial position. | L11: 0.23
B12: Debt to Total Assets Ratio | C12: Long Term Debt / Total Assets | E12: It measures how much of total assets is financed by the debt. | F12: ='standalone- balance sheet'!B11/'standalone- balance sheet'!B44 -> 0 | G12: ='standalone- balance sheet'!C11/'standalone- balance sheet'!C44 -> 0.0084140495 | H12: ='standalone- balance sheet'!D11/'standalone- balance sheet'!D44 -> 0 | I12: ='standalone- balance sheet'!E11/'standalone- balance sheet'!E44 -> 0.06526685 | J12: ='standalone- balance sheet'!F11/'standalone- balance sheet'!F44 -> 0.086606999
B13: Proprietary Ratio | C13: Proprietary Funds / Total Assets | E13: It measures the proportion of total assets financed by shareholders | F13: =F14/'standalone- balance sheet'!B44 -> 0.72181613 | G13: =G14/'standalone- balance sheet'!C44 -> 0.70349716 | H13: =H14/'standalone- balance sheet'!D44 -> 0.69467183 | I13: =I14/'standalone- balance sheet'!E44 -> 0.42361835 | J13: =J14/'standalone- balance sheet'!F44 -> 0.34610644
D14: Proprietary fund includes Equity Share Capital + Preference Share Capital + Reserve & Surplus. Total assets exclude ctitious assets and losses. | F14: ='standalone- balance sheet'!B5+'standalone- balance sheet'!B7 -> 766.28 | G14: ='standalone- balance sheet'!C5+'standalone- balance sheet'!C7 -> 647.14 | H14: ='standalone- balance sheet'!D5+'standalone- balance sheet'!D7 -> 563.49 | I14: ='standalone- balance sheet'!E5+'standalone- balance sheet'!E7 -> 178.75 | J14: ='standalone- balance sheet'!F5+'standalone- balance sheet'!F7 -> 129.16
B15: COVERAGE RATIO
B16: Debt Service Coverage Ratio (DSCR) | C16: Earnings available for debt services / Interest + Instalments | D16: EBITDA- Cash Taxes/ Interest+ CPLTD. Can be done later through cash flow also | E16: It measures the ability to meet the commitment of various debt services like interest, instalment etc. Ideal ratio is 2.
B17: Interest Coverage Ratio | C17: EBIT / Interest | E17: It measures the ability of the business to meet interest. Ideal ratio is > 1. | F17: =F34/'standalone-income statemen'!B19 -> 138.84783 | G17: =G34/'standalone-income statemen'!C19 -> 110.43609 | H17: =H34/'standalone-income statemen'!D19 -> 33.099738 | I17: =I34/'standalone-income statemen'!E19 -> 16.570662 | J17: =J34/'standalone-income statemen'!F19 -> 11.959227
B18: ACTIVITY / TURNOVER RATIO
B19: Total Asset Turnover Ratio | C19: Sales / Average Total Assets | E19: A measure of total asset utilisation. It helps to answer the question - What sales are being generated by each rupee’s worth of assets invested in the business? | F19: ='standalone-income statemen'!B9/(('standalone- balance sheet'!B44+'standalone- balance sheet'!C44)/2) -> 1.0783098 | G19: ='standalone-income statemen'!C9/(('standalone- balance sheet'!C44+'standalone- balance sheet'!D44)/2) -> 1.0412986 | H19: ='standalone-income statemen'!D9/(('standalone- balance sheet'!D44+'standalone- balance sheet'!E44)/2) -> 1.1676885 | I19: ='standalone-income statemen'!E9/(('standalone- balance sheet'!E44+'standalone- balance sheet'!F44)/2) -> 1.5640516 | J19: ='standalone-income statemen'!F9/(('standalone- balance sheet'!F44+'standalone- balance sheet'!G44)/2) -> 2.8552977 | K19: The total asset turnover ratio indicates how well a company can generate revenue from its assets. It indicates how efficiently the company uses its assets to generate sales. Indigo has a higher ratio than the industry average which means that Indigo is generating more sales from each unit of its assets than its peers in this sector. It is utilising its assets wisely and putting them to use. This serves as proof of effective asset management and operational efficiency. | L19: 0.76
B20: Fixed Assets Turnover Ratio | C20: Sales or COGS / Fixed Assets | E20: This ratio is about fixed asset capacity. A reducing sales or profit being generated from each rupee invested in fixed assets may indicate overcapacity or poorer- performing equipment | F20: ='standalone-income statemen'!B9/'standalone- balance sheet'!B30 -> 2.071973 | G20: ='standalone-income statemen'!C9/'standalone- balance sheet'!C30 -> 2.9616838 | H20: ='standalone-income statemen'!D9/'standalone- balance sheet'!D30 -> 2.8518519 | I20: ='standalone-income statemen'!E9/'standalone- balance sheet'!E30 -> 3.080757 | J20: ='standalone-income statemen'!F9/'standalone- balance sheet'!F30 -> 3.4832952 | K20: This uses a subset of the total assets to identify how well the company is utilising its fixed assets to generate sales and revenue. Again Indigo Paints has a higher ratio than its industry average which is an indicator of its good management and productive use of assets. | L20: 1.73
B21: Inventory Turnover Ratio | C21: COGS or Sales / Average Inventory | E21: Measures how efficiently the firm uses its inventory | F21: ='standalone-income statemen'!B15/(('standalone- balance sheet'!B38+'standalone- balance sheet'!C38)/2) -> 4.8970176 | G21: ='standalone-income statemen'!C15/(('standalone- balance sheet'!C38+'standalone- balance sheet'!D38)/2) -> 4.7919394 | H21: ='standalone-income statemen'!D15/(('standalone- balance sheet'!D38+'standalone- balance sheet'!E38)/2) -> 4.246048 | I21: ='standalone-income statemen'!E15/(('standalone- balance sheet'!E38+'standalone- balance sheet'!F38)/2) -> 4.396331 | J21: ='standalone-income statemen'!F15/(('standalone- balance sheet'!F38+'standalone- balance sheet'!G38)/2) -> 8.5538728 | K21: This ratio is an indicator of how well the company can turn over inventory and generate sales. Here Indigo Paints has a lower Inventory Turnover Ratio as compared to its industry average which reflects that the company might have excess unsold inventory and take a little longer to sell its inventory as compared to its peers in the industry. However, there is only a small difference between the company's ratio and industry average which is not a concern for investors given the industry is of paints and varnish. | L21: 5.1
D22: Avg Inventory = OS + CS / 2 | F22: 4.9 | G22: 4.79 | H22: 4.25 | I22: 8.14 | J22: 7.73
B23: Receivable Turnover | C23: Annual Net Credit Sales / Receivables | D23: total op revenue/avg of trade recveiables | E23: Indicates quality of receivables and how successful the firm is in its collections. | F23: ='standalone-income statemen'!B9/(('standalone- balance sheet'!B39+'standalone- balance sheet'!C39)/2) -> 5.7474177 | G23: ='standalone-income statemen'!C9/(('standalone- balance sheet'!C39+'standalone- balance sheet'!D39)/2) -> 6.1553749 | H23: ='standalone-income statemen'!D9/(('standalone- balance sheet'!D39+'standalone- balance sheet'!E39)/2) -> 6.3808384 | I23: ='standalone-income statemen'!E9/(('standalone- balance sheet'!E39+'standalone- balance sheet'!F39)/2) -> 5.9698541 | J23: ='standalone-income statemen'!F9/(('standalone- balance sheet'!F39+'standalone- balance sheet'!G39)/2) -> 10.260376 | K23: This ratio indicates how efficiently and quickly a company can manage to get its receivables and convert them to cash in a given period. Indigo Paints has a low Receivable Turnover Ratio as compared to its peers which suggests that it is not very efficient and takes longer than its industry peers to convert receivables to cash. Indigo Paints should make amends to its policies and ensure timely receival of its payments from customers and improve its collection process. | L23: 7.4
B24: Average Collection Period / AR Days | C24: Days in a year / Receivable Turnover | E24: Average number of days that receivables are outstanding | F24: =365/F23 -> 63.506782 | G24: =365/G23 -> 59.297769 | H24: =365/H23 -> 57.202514 | I24: =365/I23 -> 61.140523 | J24: =365/J23 -> 35.573747 | K24: This ratio shows how long it takes a company to collect outstanding payments from its customers. A higher ratio indicates that it takes Indigo Paints longer than its industry peers to collect and turn receivables into cash. | L24: 49.3
B25: Payable Turnover | C25: Annual Credit Purchases / Accounts Payable | D25: cogs/trade payables avg | E25: Indicates the promptness of payment to suppliers by the firm. | F25: =F26/(('standalone- balance sheet'!B18+'standalone- balance sheet'!C18)/2) -> 3.0564334 | G25: =G26/(('standalone- balance sheet'!C18+'standalone- balance sheet'!D18)/2) -> 2.8154943 | H25: =H26/(('standalone- balance sheet'!D18+'standalone- balance sheet'!E18)/2) -> 2.4735316 | I25: =I26/(('standalone- balance sheet'!E18+'standalone- balance sheet'!F18)/2) -> 2.4856821 | J25: =J26/(('standalone- balance sheet'!F18+'standalone- balance sheet'!G18)/2) -> 4.632707
D26: COGS= Cost Of Materials Consumed+Purchase Of Stock-In Trade+Changes In Inventories Of FG,WIP And Stock-In Trade+Depreciation And Amortisation Expenses | F26: ='standalone-income statemen'!B15+'standalone-income statemen'!B16+'standalone-income statemen'!B17+'standalone-income statemen'!B20 -> 629.61 | G26: ='standalone-income statemen'!C15+'standalone-income statemen'!C16+'standalone-income statemen'!C17+'standalone-income statemen'!C20 -> 544.77 | H26: ='standalone-income statemen'!D15+'standalone-income statemen'!D16+'standalone-income statemen'!D17+'standalone-income statemen'!D20 -> 400.91 | I26: ='standalone-income statemen'!E15+'standalone-income statemen'!E16+'standalone-income statemen'!E17+'standalone-income statemen'!E20 -> 341.57 | J26: ='standalone-income statemen'!F15+'standalone-income statemen'!F16+'standalone-income statemen'!F17+'standalone-income statemen'!F20 -> 315.58
B27: Average Payment Period / AP Days | C27: Days in a year / Payable Turnover | D27: 365 | E27: Average number of days that payables are outstanding. | F27: =365/F25 -> 119.42024 | G27: =365/G25 -> 129.63976 | H27: =365/H25 -> 147.5623 | I27: =365/I25 -> 146.84098 | J27: =365/J25 -> 78.787629
B28: PROFITABILITY RATIOS
B29: Gross Profit Ratio | C29: GP / Sales * 100 | E29: This ratio tells us something about the business's ability consistently to control its production costs or to manage the margins it makes on products it buys and sells. | F29: =('standalone-income statemen'!B27/'standalone-income statemen'!B8)*100 -> 14.590997 | G29: =('standalone-income statemen'!C27/'standalone-income statemen'!C8)*100 -> 12.682104 | H29: =('standalone-income statemen'!D27/'standalone-income statemen'!D8)*100 -> 13.599556 | I29: =('standalone-income statemen'!E27/'standalone-income statemen'!E8)*100 -> 10.843974 | J29: =('standalone-income statemen'!F27/'standalone-income statemen'!F8)*100 -> 6.3854947
B30: Net Profit Ratio | C30: NP / Sales * 100 | E30: It measures the relationship between net profit and sales of the business. | F30: =('standalone-income statemen'!B37/'standalone-income statemen'!B9)*100 -> 12.350117 | G30: =('standalone-income statemen'!C37/'standalone-income statemen'!C9)*100 -> 9.3257292 | H30: =('standalone-income statemen'!D37/'standalone-income statemen'!D9)*100 -> 9.8409612 | I30: =('standalone-income statemen'!E37/'standalone-income statemen'!E9)*100 -> 7.6887202 | J30: =('standalone-income statemen'!F37/'standalone-income statemen'!F9)*100 -> 5.0434521 | K30: Net Profit Ratio is indicative of how much profit a company earns in relation to its total revenue. Though the Net Profit Ratio is good for Indigo Paints, it is still lower as compared to the industry average. This indicates that Indigo Paints on average is less profitable than its peers. | L30: 0.13
B31: Return on Investment | C31: Profit or Earnings After Tax / Equity Funds or Capital Employed or Assets | E31: It measures overall return of the business on investment/equity funds/capital employed/ assets. | F31: =('standalone-income statemen'!B35/F10)*100 -> 16.543786 | G31: =('standalone-income statemen'!C35/G10)*100 -> 12.439504 | H31: =('standalone-income statemen'!D35/H10)*100 -> 12.157664 | I31: =('standalone-income statemen'!E35/I10)*100 -> 20.19771 | J31: =('standalone-income statemen'!F35/J10)*100 -> 14.5204
B32: Return on Assets (ROA) | C32: PAT / Total Assets | E32: It measures net profit per rupee of average total assets. | F32: =('standalone-income statemen'!B35/'standalone- balance sheet'!B44)*100 -> 12.42841 | G32: =('standalone-income statemen'!C35/'standalone- balance sheet'!C44)*100 -> 9.136962 | H32: =('standalone-income statemen'!D35/'standalone- balance sheet'!D44)*100 -> 8.734405 | I32: =('standalone-income statemen'!E35/'standalone- balance sheet'!E44)*100 -> 11.330458 | J32: =('standalone-income statemen'!F35/'standalone- balance sheet'!F44)*100 -> 7.2002787
B33: Return on Capital Employed | C33: EBIT / Capital Employed * 100 | D33: Ebitda: profit before extraordinary items+finance cost+depreciation and ammortization | E33: It measures overall earnings (either pre- tax or post tax) on total capital employed | F33: =(F35/F10)*100 -> 19.718628 | G33: =(G35/G10)*100 -> 17.113384 | H33: =(H35/H10)*100 -> 17.45487 | I33: =(I35/I10)*100 -> 30.847873 | J33: =(J35/J10)*100 -> 20.902459
D34: Ebitda value | F34: ='standalone-income statemen'!B27+'standalone-income statemen'!B20+'standalone-income statemen'!B19 -> 191.61 | G34: ='standalone-income statemen'!C27+'standalone-income statemen'!C20+'standalone-income statemen'!C19 -> 146.88 | H34: ='standalone-income statemen'!D27+'standalone-income statemen'!D20+'standalone-income statemen'!D19 -> 126.11 | I34: ='standalone-income statemen'!E27+'standalone-income statemen'!E20+'standalone-income statemen'!E19 -> 92.63 | J34: ='standalone-income statemen'!F27+'standalone-income statemen'!F20+'standalone-income statemen'!F19 -> 55.73
D35: Ebit value | F35: =F34-'standalone-income statemen'!B20 -> 157.26 | G35: =G34-'standalone-income statemen'!C20 -> 115.63 | H35: =H34-'standalone-income statemen'!D20 -> 101.72 | I35: =I34-'standalone-income statemen'!E20 -> 73.02 | J35: =J34-'standalone-income statemen'!F20 -> 38.68
B36: ROCE (Pre-tax)
D37: ((Current tax+deferred tax )/PBT)*100 | F37: =(('standalone-income statemen'!B31+'standalone-income statemen'!B32)/'standalone-income statemen'!B29)*100 -> 25.833975 | G37: =(('standalone-income statemen'!C31+'standalone-income statemen'!C32)/'standalone-income statemen'!C29)*100 -> 26.456693 | H37: =(('standalone-income statemen'!D31+'standalone-income statemen'!D32)/'standalone-income statemen'!D29)*100 -> 28.495557 | I37: =(('standalone-income statemen'!E31+'standalone-income statemen'!E32)/'standalone-income statemen'!E29)*100 -> 29.082011 | J37: =(('standalone-income statemen'!F31+'standalone-income statemen'!F32)/'standalone-income statemen'!F29)*100 -> 20.290715
B38: Return on Capital Employed | C38: EBIT (1-t) / Capital Employed * 100 | E38: It measures overall earnings (either pre- tax or post tax) on total capital employed | F38: =((F35*F37)/F10)*100 -> 509.41053 | G38: =((G35*G37)/G10)*100 -> 452.76354 | H38: =((H35*H37)/H10)*100 -> 497.38624 | I38: =((I35*I37)/I10)*100 -> 897.11818 | J38: =((J35*J37)/J10)*100 -> 424.12583
B39: ROCE (Post -tax) | D39: Tax rate | F39: 0.2517 | G39: 0.2517 | H39: 0.2517 | I39: 0.2517 | J39: 0.2517
B40: Return on Equity (ROE) | C40: (PAT - Preference Dividend ) / Net Worth or Equity Shareholders Funds | E40: It indicates earnings available to equity shareholders in comparison to equity shareholders’ net worth. | F40: =('standalone-income statemen'!B35/'standalone- balance sheet'!B9)*100 -> 16.999729 | G40: =('standalone-income statemen'!C35/'standalone- balance sheet'!C9)*100 -> 12.933555 | H40: =('standalone-income statemen'!D35/'standalone- balance sheet'!D9)*100 -> 12.573426 | I40: =('standalone-income statemen'!E35/'standalone- balance sheet'!E9)*100 -> 26.746853 | J40: =('standalone-income statemen'!F35/'standalone- balance sheet'!F9)*100 -> 20.803654 | K40: ROE indicates how much profit the business is generating on the invested equity. 17% ROE is still a good number, however, when compared to the industry average Indigo Paints is not performing up to the mark of its peers. When the peers are generating 18.4% returns on equity on average, Indigo is only generating 17%. This would make it a less ideal choice for investors/shareholders to put money in. | L40: 0.184
...

Sheet Interpretation
A1: Within 500 words submit an interpretation of the financial position of the company purely based on the ratios computed.
A3: Indigo Paints has demonstrated a strong position in the Paint and Varnish industry with some improvements to make. Firstly, in terms of the company's liquidity ratios, it has surpassed industry averages of both Quick Ratio and Current Ratio and exhibited a commendable position of a low-risk, liquid company, as desired by the investors. This demonstrates excellent liquidity management, with effective and productive asset management to meet short-term liability. This showcases strong management with an effective and wise financial approach. Secondly, looking at the Capital Structure Ratios, Indigo Paints has again shown a robust performance regarding its reliance on Debt with a negligible debt-to-equity ratio. It is in the top position among its peers concerning this ratio, which indicates its low financial risk and no burden of debt which is a good sign for investors (though one may also say that it is good to have little debt as the cost of debt is lesser than that of equity, and debt can also provide tax benefits from interest payments. However, this is subjective.) Thirdly, when it comes to turnover ratios, the company outperforms industry averages in both total and fixed asset turnover ratios, indicating efficient utilization of assets to generate revenue. This operational efficiency is a positive indicator of effective management practices and the potential for cost-effective capital investments. Lastly, when it comes to profitability ratios, the company has underperformed as compared to its peers and has not been able to generate profits equal to or more than the industry average which is a weakness that can be improved upon as the ratios are not bad, just lower than the industry standards. The company has shown an overall strong performance which makes it a good choice for investors, with some improvements in inventory and receivables management, as well as in optimizing working capital efficiency and increasing profitability by making some amendments in the cost structure, value proposition, etc of the company.
